[2024-06-06T13:06:23.948+0000] {taskinstance.py:1157} INFO - Dependencies all met for dep_context=non-requeueable deps ti=<TaskInstance: my_python_dag.elastic_metro_station manual__2024-06-06T13:06:22.782704+00:00 [queued]>
[2024-06-06T13:06:23.953+0000] {taskinstance.py:1157} INFO - Dependencies all met for dep_context=requeueable deps ti=<TaskInstance: my_python_dag.elastic_metro_station manual__2024-06-06T13:06:22.782704+00:00 [queued]>
[2024-06-06T13:06:23.953+0000] {taskinstance.py:1359} INFO - Starting attempt 1 of 2
[2024-06-06T13:06:24.088+0000] {taskinstance.py:1380} INFO - Executing <Task(PythonOperator): elastic_metro_station> on 2024-06-06 13:06:22.782704+00:00
[2024-06-06T13:06:24.091+0000] {standard_task_runner.py:57} INFO - Started process 969 to run task
[2024-06-06T13:06:24.094+0000] {standard_task_runner.py:84} INFO - Running: ['***', 'tasks', 'run', 'my_python_dag', 'elastic_metro_station', 'manual__2024-06-06T13:06:22.782704+00:00', '--job-id', '184', '--raw', '--subdir', 'DAGS_FOLDER/fetch_from_data_sources.py', '--cfg-path', '/tmp/tmp5o2bwtux']
[2024-06-06T13:06:24.096+0000] {standard_task_runner.py:85} INFO - Job 184: Subtask elastic_metro_station
[2024-06-06T13:06:24.119+0000] {task_command.py:415} INFO - Running <TaskInstance: my_python_dag.elastic_metro_station manual__2024-06-06T13:06:22.782704+00:00 [running]> on host 9e4bf1cd7746
[2024-06-06T13:06:24.154+0000] {taskinstance.py:1660} INFO - Exporting env vars: AIRFLOW_CTX_DAG_OWNER='***' AIRFLOW_CTX_DAG_ID='my_python_dag' AIRFLOW_CTX_TASK_ID='elastic_metro_station' AIRFLOW_CTX_EXECUTION_DATE='2024-06-06T13:06:22.782704+00:00' AIRFLOW_CTX_TRY_NUMBER='1' AIRFLOW_CTX_DAG_RUN_ID='manual__2024-06-06T13:06:22.782704+00:00'
[2024-06-06T13:06:24.155+0000] {logging_mixin.py:151} INFO - Hello
[2024-06-06T13:07:08.362+0000] {taskinstance.py:1935} ERROR - Task failed with exception
Traceback (most recent call last):
  File "/home/airflow/.local/lib/python3.8/site-packages/urllib3/connectionpool.py", line 714, in urlopen
    httplib_response = self._make_request(
  File "/home/airflow/.local/lib/python3.8/site-packages/urllib3/connectionpool.py", line 466, in _make_request
    six.raise_from(e, None)
  File "<string>", line 3, in raise_from
  File "/home/airflow/.local/lib/python3.8/site-packages/urllib3/connectionpool.py", line 461, in _make_request
    httplib_response = conn.getresponse()
  File "/usr/local/lib/python3.8/http/client.py", line 1348, in getresponse
    response.begin()
  File "/usr/local/lib/python3.8/http/client.py", line 316, in begin
    version, status, reason = self._read_status()
  File "/usr/local/lib/python3.8/http/client.py", line 285, in _read_status
    raise RemoteDisconnected("Remote end closed connection without"
http.client.RemoteDisconnected: Remote end closed connection without response

During handling of the above exception, another exception occurred:

Traceback (most recent call last):
  File "/home/airflow/.local/lib/python3.8/site-packages/requests/adapters.py", line 486, in send
    resp = conn.urlopen(
  File "/home/airflow/.local/lib/python3.8/site-packages/urllib3/connectionpool.py", line 798, in urlopen
    retries = retries.increment(
  File "/home/airflow/.local/lib/python3.8/site-packages/urllib3/util/retry.py", line 550, in increment
    raise six.reraise(type(error), error, _stacktrace)
  File "/home/airflow/.local/lib/python3.8/site-packages/urllib3/packages/six.py", line 769, in reraise
    raise value.with_traceback(tb)
  File "/home/airflow/.local/lib/python3.8/site-packages/urllib3/connectionpool.py", line 714, in urlopen
    httplib_response = self._make_request(
  File "/home/airflow/.local/lib/python3.8/site-packages/urllib3/connectionpool.py", line 466, in _make_request
    six.raise_from(e, None)
  File "<string>", line 3, in raise_from
  File "/home/airflow/.local/lib/python3.8/site-packages/urllib3/connectionpool.py", line 461, in _make_request
    httplib_response = conn.getresponse()
  File "/usr/local/lib/python3.8/http/client.py", line 1348, in getresponse
    response.begin()
  File "/usr/local/lib/python3.8/http/client.py", line 316, in begin
    version, status, reason = self._read_status()
  File "/usr/local/lib/python3.8/http/client.py", line 285, in _read_status
    raise RemoteDisconnected("Remote end closed connection without"
urllib3.exceptions.ProtocolError: ('Connection aborted.', RemoteDisconnected('Remote end closed connection without response'))

During handling of the above exception, another exception occurred:

Traceback (most recent call last):
  File "/home/airflow/.local/lib/python3.8/site-packages/airflow/operators/python.py", line 192, in execute
    return_value = self.execute_callable()
  File "/home/airflow/.local/lib/python3.8/site-packages/airflow/operators/python.py", line 209, in execute_callable
    return self.python_callable(*self.op_args, **self.op_kwargs)
  File "/opt/airflow/dags/stations_functions.py", line 78, in elastic_metro_station
    res = create_info_station()
  File "/opt/airflow/dags/stations_functions.py", line 33, in create_info_station
    innerHashMap = retrieveInfosSortieMetro(newUrl, number)
  File "/opt/airflow/dags/stations_functions.py", line 43, in retrieveInfosSortieMetro
    response = requests.get(url)
  File "/home/airflow/.local/lib/python3.8/site-packages/requests/api.py", line 73, in get
    return request("get", url, params=params, **kwargs)
  File "/home/airflow/.local/lib/python3.8/site-packages/requests/api.py", line 59, in request
    return session.request(method=method, url=url, **kwargs)
  File "/home/airflow/.local/lib/python3.8/site-packages/requests/sessions.py", line 589, in request
    resp = self.send(prep, **send_kwargs)
  File "/home/airflow/.local/lib/python3.8/site-packages/requests/sessions.py", line 703, in send
    r = adapter.send(request, **kwargs)
  File "/home/airflow/.local/lib/python3.8/site-packages/requests/adapters.py", line 501, in send
    raise ConnectionError(err, request=request)
requests.exceptions.ConnectionError: ('Connection aborted.', RemoteDisconnected('Remote end closed connection without response'))
[2024-06-06T13:07:08.380+0000] {taskinstance.py:1398} INFO - Marking task as UP_FOR_RETRY. dag_id=my_python_dag, task_id=elastic_metro_station, execution_date=20240606T130622, start_date=20240606T130623, end_date=20240606T130708
[2024-06-06T13:07:08.390+0000] {standard_task_runner.py:104} ERROR - Failed to execute job 184 for task elastic_metro_station (('Connection aborted.', RemoteDisconnected('Remote end closed connection without response')); 969)
[2024-06-06T13:07:08.418+0000] {local_task_job_runner.py:228} INFO - Task exited with return code 1
[2024-06-06T13:07:08.428+0000] {taskinstance.py:2776} INFO - 0 downstream tasks scheduled from follow-on schedule check
