[2024-06-04T11:00:50.839+0000] {taskinstance.py:1157} INFO - Dependencies all met for dep_context=non-requeueable deps ti=<TaskInstance: my_python_dag.fetch_and_insert_into_elasticsearch_emplacement_stations manual__2024-06-04T11:00:50.064554+00:00 [queued]>
[2024-06-04T11:00:50.844+0000] {taskinstance.py:1157} INFO - Dependencies all met for dep_context=requeueable deps ti=<TaskInstance: my_python_dag.fetch_and_insert_into_elasticsearch_emplacement_stations manual__2024-06-04T11:00:50.064554+00:00 [queued]>
[2024-06-04T11:00:50.845+0000] {taskinstance.py:1359} INFO - Starting attempt 1 of 2
[2024-06-04T11:00:50.994+0000] {taskinstance.py:1380} INFO - Executing <Task(PythonOperator): fetch_and_insert_into_elasticsearch_emplacement_stations> on 2024-06-04 11:00:50.064554+00:00
[2024-06-04T11:00:50.998+0000] {standard_task_runner.py:57} INFO - Started process 979 to run task
[2024-06-04T11:00:51.001+0000] {standard_task_runner.py:84} INFO - Running: ['***', 'tasks', 'run', 'my_python_dag', 'fetch_and_insert_into_elasticsearch_emplacement_stations', 'manual__2024-06-04T11:00:50.064554+00:00', '--job-id', '105', '--raw', '--subdir', 'DAGS_FOLDER/fetch_from_data_sources.py', '--cfg-path', '/tmp/tmpbz7au96d']
[2024-06-04T11:00:51.004+0000] {standard_task_runner.py:85} INFO - Job 105: Subtask fetch_and_insert_into_elasticsearch_emplacement_stations
[2024-06-04T11:00:51.029+0000] {task_command.py:415} INFO - Running <TaskInstance: my_python_dag.fetch_and_insert_into_elasticsearch_emplacement_stations manual__2024-06-04T11:00:50.064554+00:00 [running]> on host 9e4bf1cd7746
[2024-06-04T11:00:51.066+0000] {taskinstance.py:1660} INFO - Exporting env vars: AIRFLOW_CTX_DAG_OWNER='***' AIRFLOW_CTX_DAG_ID='my_python_dag' AIRFLOW_CTX_TASK_ID='fetch_and_insert_into_elasticsearch_emplacement_stations' AIRFLOW_CTX_EXECUTION_DATE='2024-06-04T11:00:50.064554+00:00' AIRFLOW_CTX_TRY_NUMBER='1' AIRFLOW_CTX_DAG_RUN_ID='manual__2024-06-04T11:00:50.064554+00:00'
[2024-06-04T11:00:51.067+0000] {logging_mixin.py:151} INFO - Fetching data from JSON
[2024-06-04T11:00:51.219+0000] {_transport.py:359} INFO - PUT http://elasticsearch:9200/emplacement-stations-idf/_doc/988_Cit%C3%A9%20Universitaire [status:N/A duration:0.004s]
[2024-06-04T11:00:51.219+0000] {_node_pool.py:246} WARNING - Node <Urllib3HttpNode(http://elasticsearch:9200)> has failed for 1 times in a row, putting on 1 second timeout
[2024-06-04T11:00:51.220+0000] {_transport.py:396} WARNING - Retrying request after failure (attempt 0 of 3)
Traceback (most recent call last):
  File "/home/airflow/.local/lib/python3.8/site-packages/elastic_transport/_transport.py", line 329, in perform_request
    meta, raw_data = node.perform_request(
  File "/home/airflow/.local/lib/python3.8/site-packages/elastic_transport/_node/_http_urllib3.py", line 199, in perform_request
    raise err from None
elastic_transport.ConnectionError: Connection error caused by: ProtocolError(('Connection aborted.', RemoteDisconnected('Remote end closed connection without response')))
[2024-06-04T11:00:51.223+0000] {_transport.py:359} INFO - PUT http://elasticsearch:9200/emplacement-stations-idf/_doc/988_Cit%C3%A9%20Universitaire [status:N/A duration:0.001s]
[2024-06-04T11:00:51.223+0000] {_node_pool.py:246} WARNING - Node <Urllib3HttpNode(http://elasticsearch:9200)> has failed for 2 times in a row, putting on 2 second timeout
[2024-06-04T11:00:51.223+0000] {_transport.py:396} WARNING - Retrying request after failure (attempt 1 of 3)
Traceback (most recent call last):
  File "/home/airflow/.local/lib/python3.8/site-packages/elastic_transport/_transport.py", line 329, in perform_request
    meta, raw_data = node.perform_request(
  File "/home/airflow/.local/lib/python3.8/site-packages/elastic_transport/_node/_http_urllib3.py", line 199, in perform_request
    raise err from None
elastic_transport.ConnectionError: Connection error caused by: ProtocolError(('Connection aborted.', RemoteDisconnected('Remote end closed connection without response')))
[2024-06-04T11:00:51.224+0000] {_transport.py:359} INFO - PUT http://elasticsearch:9200/emplacement-stations-idf/_doc/988_Cit%C3%A9%20Universitaire [status:N/A duration:0.001s]
[2024-06-04T11:00:51.225+0000] {_node_pool.py:246} WARNING - Node <Urllib3HttpNode(http://elasticsearch:9200)> has failed for 3 times in a row, putting on 4 second timeout
[2024-06-04T11:00:51.225+0000] {_transport.py:396} WARNING - Retrying request after failure (attempt 2 of 3)
Traceback (most recent call last):
  File "/home/airflow/.local/lib/python3.8/site-packages/elastic_transport/_transport.py", line 329, in perform_request
    meta, raw_data = node.perform_request(
  File "/home/airflow/.local/lib/python3.8/site-packages/elastic_transport/_node/_http_urllib3.py", line 199, in perform_request
    raise err from None
elastic_transport.ConnectionError: Connection error caused by: ProtocolError(('Connection aborted.', RemoteDisconnected('Remote end closed connection without response')))
[2024-06-04T11:00:51.227+0000] {_transport.py:359} INFO - PUT http://elasticsearch:9200/emplacement-stations-idf/_doc/988_Cit%C3%A9%20Universitaire [status:N/A duration:0.001s]
[2024-06-04T11:00:51.227+0000] {_node_pool.py:246} WARNING - Node <Urllib3HttpNode(http://elasticsearch:9200)> has failed for 4 times in a row, putting on 8 second timeout
[2024-06-04T11:00:51.227+0000] {taskinstance.py:1935} ERROR - Task failed with exception
Traceback (most recent call last):
  File "/home/airflow/.local/lib/python3.8/site-packages/airflow/operators/python.py", line 192, in execute
    return_value = self.execute_callable()
  File "/home/airflow/.local/lib/python3.8/site-packages/airflow/operators/python.py", line 209, in execute_callable
    return self.python_callable(*self.op_args, **self.op_kwargs)
  File "/opt/airflow/dags/stations_functions.py", line 117, in fetch_and_insert_into_elasticsearch_emplacement_stations
    insert_into_elasticsearch(content)
  File "/opt/airflow/dags/stations_functions.py", line 111, in insert_into_elasticsearch
    client.index(index="emplacement-stations-idf", id=unique_id, body=item)
  File "/home/airflow/.local/lib/python3.8/site-packages/elasticsearch/_sync/client/utils.py", line 414, in wrapped
    return api(*args, **kwargs)
  File "/home/airflow/.local/lib/python3.8/site-packages/elasticsearch/_sync/client/__init__.py", line 2318, in index
    return self.perform_request(  # type: ignore[return-value]
  File "/home/airflow/.local/lib/python3.8/site-packages/elasticsearch/_sync/client/_base.py", line 285, in perform_request
    meta, resp_body = self.transport.perform_request(
  File "/home/airflow/.local/lib/python3.8/site-packages/elastic_transport/_transport.py", line 329, in perform_request
    meta, raw_data = node.perform_request(
  File "/home/airflow/.local/lib/python3.8/site-packages/elastic_transport/_node/_http_urllib3.py", line 199, in perform_request
    raise err from None
elastic_transport.ConnectionError: Connection error caused by: ConnectionError(Connection error caused by: ProtocolError(('Connection aborted.', RemoteDisconnected('Remote end closed connection without response'))))
[2024-06-04T11:00:51.234+0000] {taskinstance.py:1398} INFO - Marking task as UP_FOR_RETRY. dag_id=my_python_dag, task_id=fetch_and_insert_into_elasticsearch_emplacement_stations, execution_date=20240604T110050, start_date=20240604T110050, end_date=20240604T110051
[2024-06-04T11:00:51.243+0000] {standard_task_runner.py:104} ERROR - Failed to execute job 105 for task fetch_and_insert_into_elasticsearch_emplacement_stations (Connection error caused by: ConnectionError(Connection error caused by: ProtocolError(('Connection aborted.', RemoteDisconnected('Remote end closed connection without response')))); 979)
[2024-06-04T11:00:51.261+0000] {local_task_job_runner.py:228} INFO - Task exited with return code 1
[2024-06-04T11:00:51.271+0000] {taskinstance.py:2776} INFO - 0 downstream tasks scheduled from follow-on schedule check
