[2024-06-04T09:24:31.052+0000] {taskinstance.py:1157} INFO - Dependencies all met for dep_context=non-requeueable deps ti=<TaskInstance: my_python_dag.fetch_and_insert_into_elasticsearch_emplacement_stations manual__2024-06-04T09:18:59.932650+00:00 [queued]>
[2024-06-04T09:24:31.056+0000] {taskinstance.py:1157} INFO - Dependencies all met for dep_context=requeueable deps ti=<TaskInstance: my_python_dag.fetch_and_insert_into_elasticsearch_emplacement_stations manual__2024-06-04T09:18:59.932650+00:00 [queued]>
[2024-06-04T09:24:31.056+0000] {taskinstance.py:1359} INFO - Starting attempt 2 of 2
[2024-06-04T09:24:31.062+0000] {taskinstance.py:1380} INFO - Executing <Task(PythonOperator): fetch_and_insert_into_elasticsearch_emplacement_stations> on 2024-06-04 09:18:59.932650+00:00
[2024-06-04T09:24:31.065+0000] {standard_task_runner.py:57} INFO - Started process 1210 to run task
[2024-06-04T09:24:31.068+0000] {standard_task_runner.py:84} INFO - Running: ['***', 'tasks', 'run', 'my_python_dag', 'fetch_and_insert_into_elasticsearch_emplacement_stations', 'manual__2024-06-04T09:18:59.932650+00:00', '--job-id', '70', '--raw', '--subdir', 'DAGS_FOLDER/fetch_from_data_sources.py', '--cfg-path', '/tmp/tmpwnj1uvms']
[2024-06-04T09:24:31.070+0000] {standard_task_runner.py:85} INFO - Job 70: Subtask fetch_and_insert_into_elasticsearch_emplacement_stations
[2024-06-04T09:24:31.249+0000] {task_command.py:415} INFO - Running <TaskInstance: my_python_dag.fetch_and_insert_into_elasticsearch_emplacement_stations manual__2024-06-04T09:18:59.932650+00:00 [running]> on host 28f1ec4f9f22
[2024-06-04T09:24:31.282+0000] {taskinstance.py:1660} INFO - Exporting env vars: AIRFLOW_CTX_DAG_OWNER='***' AIRFLOW_CTX_DAG_ID='my_python_dag' AIRFLOW_CTX_TASK_ID='fetch_and_insert_into_elasticsearch_emplacement_stations' AIRFLOW_CTX_EXECUTION_DATE='2024-06-04T09:18:59.932650+00:00' AIRFLOW_CTX_TRY_NUMBER='2' AIRFLOW_CTX_DAG_RUN_ID='manual__2024-06-04T09:18:59.932650+00:00'
[2024-06-04T09:24:31.283+0000] {logging_mixin.py:151} INFO - Fetching data from JSON
[2024-06-04T09:24:31.816+0000] {_transport.py:336} INFO - PUT https://e7bce3a6df364700956f06c04d5fc655.us-central1.gcp.cloud.es.io:443/emplacement-stations-idf/_doc/988_Cit%C3%A9%20Universitaire [status:503 duration:0.417s]
[2024-06-04T09:24:31.818+0000] {_node_pool.py:246} WARNING - Node <Urllib3HttpNode(https://e7bce3a6df364700956f06c04d5fc655.us-central1.gcp.cloud.es.io:443)> has failed for 1 times in a row, putting on 1 second timeout
[2024-06-04T09:24:31.819+0000] {_transport.py:428} WARNING - Retrying request after non-successful status 503 (attempt 0 of 3)
[2024-06-04T09:24:31.929+0000] {_transport.py:336} INFO - PUT https://e7bce3a6df364700956f06c04d5fc655.us-central1.gcp.cloud.es.io:443/emplacement-stations-idf/_doc/988_Cit%C3%A9%20Universitaire [status:503 duration:0.109s]
[2024-06-04T09:24:31.929+0000] {_node_pool.py:246} WARNING - Node <Urllib3HttpNode(https://e7bce3a6df364700956f06c04d5fc655.us-central1.gcp.cloud.es.io:443)> has failed for 2 times in a row, putting on 2 second timeout
[2024-06-04T09:24:31.930+0000] {_transport.py:428} WARNING - Retrying request after non-successful status 503 (attempt 1 of 3)
[2024-06-04T09:24:32.039+0000] {_transport.py:336} INFO - PUT https://e7bce3a6df364700956f06c04d5fc655.us-central1.gcp.cloud.es.io:443/emplacement-stations-idf/_doc/988_Cit%C3%A9%20Universitaire [status:503 duration:0.109s]
[2024-06-04T09:24:32.040+0000] {_node_pool.py:246} WARNING - Node <Urllib3HttpNode(https://e7bce3a6df364700956f06c04d5fc655.us-central1.gcp.cloud.es.io:443)> has failed for 3 times in a row, putting on 4 second timeout
[2024-06-04T09:24:32.040+0000] {_transport.py:428} WARNING - Retrying request after non-successful status 503 (attempt 2 of 3)
[2024-06-04T09:24:32.150+0000] {_transport.py:336} INFO - PUT https://e7bce3a6df364700956f06c04d5fc655.us-central1.gcp.cloud.es.io:443/emplacement-stations-idf/_doc/988_Cit%C3%A9%20Universitaire [status:503 duration:0.109s]
[2024-06-04T09:24:32.151+0000] {_node_pool.py:246} WARNING - Node <Urllib3HttpNode(https://e7bce3a6df364700956f06c04d5fc655.us-central1.gcp.cloud.es.io:443)> has failed for 4 times in a row, putting on 8 second timeout
[2024-06-04T09:24:32.153+0000] {taskinstance.py:1935} ERROR - Task failed with exception
Traceback (most recent call last):
  File "/home/airflow/.local/lib/python3.8/site-packages/airflow/operators/python.py", line 192, in execute
    return_value = self.execute_callable()
  File "/home/airflow/.local/lib/python3.8/site-packages/airflow/operators/python.py", line 209, in execute_callable
    return self.python_callable(*self.op_args, **self.op_kwargs)
  File "/opt/airflow/dags/stations_functions.py", line 110, in fetch_and_insert_into_elasticsearch_emplacement_stations
    insert_into_elasticsearch(content)
  File "/opt/airflow/dags/stations_functions.py", line 104, in insert_into_elasticsearch
    client.index(index="emplacement-stations-idf", id=unique_id, body=item)
  File "/home/airflow/.local/lib/python3.8/site-packages/elasticsearch/_sync/client/utils.py", line 414, in wrapped
    return api(*args, **kwargs)
  File "/home/airflow/.local/lib/python3.8/site-packages/elasticsearch/_sync/client/__init__.py", line 2318, in index
    return self.perform_request(  # type: ignore[return-value]
  File "/home/airflow/.local/lib/python3.8/site-packages/elasticsearch/_sync/client/_base.py", line 320, in perform_request
    raise HTTP_EXCEPTIONS.get(meta.status, ApiError)(
elasticsearch.ApiError: ApiError(503, "{'ok': False, 'message': 'The requested resource is currently unavailable.'}")
[2024-06-04T09:24:32.170+0000] {taskinstance.py:1398} INFO - Marking task as FAILED. dag_id=my_python_dag, task_id=fetch_and_insert_into_elasticsearch_emplacement_stations, execution_date=20240604T091859, start_date=20240604T092431, end_date=20240604T092432
[2024-06-04T09:24:32.184+0000] {standard_task_runner.py:104} ERROR - Failed to execute job 70 for task fetch_and_insert_into_elasticsearch_emplacement_stations (ApiError(503, "{'ok': False, 'message': 'The requested resource is currently unavailable.'}"); 1210)
[2024-06-04T09:24:32.229+0000] {local_task_job_runner.py:228} INFO - Task exited with return code 1
[2024-06-04T09:24:32.351+0000] {taskinstance.py:2776} INFO - 0 downstream tasks scheduled from follow-on schedule check
